Workbook
Name Slicer_Platform: #N/A
Name Slicer_State3: #N/A

Sheet Sales_Analysis.xlsx
A1: Order_ID | B1: Customer_ID | C1: Customer_Name | D1: Gender | E1: Age | F1: Platform | G1: Order_Date | H1: Delivery_Date | I1: State | J1: City | K1: Category | L1: Product_ID | M1: Product_Name | N1: Brand | O1: Quantity | P1: Cost_Price | Q1: Selling_Price | R1: Discount_% | S1: Sales | T1: Profit | U1: Payment_Method | V1: Delivery_Status | W1: Customer_Rating | X1: Warehouse | Y1: Salesperson
A2: ORD100000 | B2: CUST10000 | C2: Ashley Cox | D2: Female | E2: 35 | F2: Flipkart | G2: 45988 | H2: 46078 | I2: Maharashtra | J2: Mumbai | K2: Home | L2: P4053 | M2: Pressure Cooker | N2: Prestige | O2: 1 | P2: 17415 | Q2: 19836.65 | R2: 20 | S2: 15869.32 | T2: 2421.65 | U2: Debit Card | V2: Cancelled | W2: 1 | X2: Mumbai Hub | Y2: Robin Hodges
A3: ORD100001 | B3: CUST10001 | C3: Rebecca Everett | D3: Female | E3: 41 | F3: Flipkart | G3: 45843 | H3: 45577 | I3: Maharashtra | J3: Pune | K3: Grocery | L3: P3274 | M3: Sunflower Oil | N3: Fortune | O3: 4 | P3: 13107 | Q3: 17607.4 | R3: 10 | S3: 63386.64 | T3: 18001.6 | U3: UPI | V3: Cancelled | W3: 2 | X3: Pune Hub | Y3: Austin Mann
A4: ORD100002 | B4: CUST10002 | C4: Jacob Dalton | D4: Male | E4: 22 | F4: Flipkart | G4: 45879 | H4: 45906 | I4: Delhi | J4: New Delhi | K4: Grocery | L4: P1312 | M4: Sunflower Oil | N4: Fortune | O4: 1 | P4: 1905 | Q4: 2290.68 | R4: 15 | S4: 1947.08 | T4: 385.68 | U4: Debit Card | V4: Cancelled | W4: 4 | X4: New Delhi Hub | Y4: Andres Wright
A5: ORD100003 | B5: CUST10003 | C5: Diana Murphy DDS | D5: Male | E5: 59 | F5: Flipkart | G5: 45608 | H5: 45927 | I5: Telangana | J5: Hyderabad | K5: Beauty | L5: P3240 | M5: Face Wash | N5: Loreal | O5: 3 | P5: 10574 | Q5: 11718.4 | R5: 20 | S5: 28124.16 | T5: 3433.2 | U5: Debit Card | V5: Delivered | W5: 2 | X5: Hyderabad Hub | Y5: Eugene Martin
A6: ORD100004 | B6: CUST10004 | C6: Henry Rojas | D6: Female | E6: 55 | F6: Flipkart | G6: 45558 | H6: 45575 | I6: Karnataka | J6: Bengaluru | K6: Beauty | L6: P5574 | M6: Face Wash | N6: Loreal | O6: 5 | P6: 19031 | Q6: 27531.63 | R6: 15 | S6: 117009.43 | T6: 42503.15 | U6: Credit Card | V6: Delivered | W6: 4 | X6: Bengaluru Hub | Y6: Amy Contreras
A7: ORD100005 | B7: CUST10005 | C7: Morgan Robinson | D7: Male | E7: 48 | F7: Flipkart | G7: 46027 | H7: 45728 | I7: Tamil Nadu | J7: Chennai | K7: Grocery | L7: P3562 | M7: Sunflower Oil | N7: Fortune | O7: 4 | P7: 7382 | Q7: 9091.91 | R7: 5 | S7: 34549.26 | T7: 6839.64 | U7: UPI | V7: Delivered | W7: 1 | X7: Chennai Hub | Y7: Mckenzie Brady
A8: ORD100006 | B8: CUST10006 | C8: Robert Peterson | D8: Female | E8: 32 | F8: Amazon | G8: 45610 | H8: 46130 | I8: Telangana | J8: Hyderabad | K8: Electronics | L8: P2671 | M8: Galaxy S24 | N8: Samsung | O8: 2 | P8: 26006 | Q8: 29271.93 | R8: 0 | S8: 58543.86 | T8: 6531.86 | U8: Debit Card | V8: Cancelled | W8: 5 | X8: Hyderabad Hub | Y8: Michele Taylor
A9: ORD100007 | B9: CUST10007 | C9: Lindsey Brown | D9: Male | E9: 54 | F9: Flipkart | G9: 45708 | H9: 45634 | I9: Karnataka | J9: Bengaluru | K9: Beauty | L9: P3840 | M9: Face Wash | N9: Loreal | O9: 3 | P9: 9411 | Q9: 12520.75 | R9: 15 | S9: 31927.91 | T9: 9329.25 | U9: Debit Card | V9: Delivered | W9: 2 | X9: Bengaluru Hub | Y9: Christina Stevens
A10: ORD100008 | B10: CUST10008 | C10: Charlotte Gilbert | D10: Female | E10: 46 | F10: Flipkart | G10: 45611 | H10: 45792 | I10: Maharashtra | J10: Mumbai | K10: Grocery | L10: P5256 | M10: Sunflower Oil | N10: Fortune | O10: 3 | P10: 18006 | Q10: 20107.58 | R10: 10 | S10: 54290.47 | T10: 6304.74 | U10: Debit Card | V10: Cancelled | W10: 3 | X10: Mumbai Hub | Y10: Clifford Newton
A11: ORD100009 | B11: CUST10009 | C11: Rachel Garcia | D11: Male | E11: 32 | F11: Flipkart | G11: 46067 | H11: 45805 | I11: Karnataka | J11: Bengaluru | K11: Beauty | L11: P3816 | M11: Face Wash | N11: Loreal | O11: 2 | P11: 2839 | Q11: 3511.61 | R11: 20 | S11: 5618.58 | T11: 1345.22 | U11: Credit Card | V11: In Transit | W11: 4 | X11: Bengaluru Hub | Y11: Jerome Campbell
A12: ORD100010 | B12: CUST10010 | C12: Travis Keller | D12: Female | E12: 46 | F12: Amazon | G12: 46069 | H12: 45474 | I12: Delhi | J12: New Delhi | K12: Fashion | L12: P2051 | M12: Air Max Shoes | N12: Nike | O12: 5 | P12: 15167 | Q12: 19780.36 | R12: 5 | S12: 93956.71 | T12: 23066.8 | U12: UPI | V12: Delivered | W12: 1 | X12: New Delhi Hub | Y12: Anthony Day
A13: ORD100011 | B13: CUST10011 | C13: Joshua Thompson | D13: Female | E13: 19 | F13: Flipkart | G13: 45854 | H13: 45561 | I13: Telangana | J13: Hyderabad | K13: Fashion | L13: P5949 | M13: Air Max Shoes | N13: Nike | O13: 4 | P13: 12428 | Q13: 15530.69 | R13: 0 | S13: 62122.76 | T13: 12410.76 | U13: COD | V13: Delivered | W13: 3 | X13: Hyderabad Hub | Y13: Devin Johnson
... A38: ORD100036 | B38: CUST10036 | C38: Sheila Townsend | D38: Female | E38: 49 | F38: Flipkart | G38: 46181 | H38: 45658 | I38: Tamil Nadu | J38: Chennai | K38: Fashion | L38: P1779 | M38: Air Max Shoes | N38: Nike | O38: 1 | P38: 26287 | Q38: 37421.5 | R38: 20 | S38: 29937.2 | T38: 11134.5 | U38: Debit Card | V38: In Transit | W38: 5 | X38: Chennai Hub | Y38: Kenneth Jackson
A39: ORD100037 | B39: CUST10037 | C39: Garrett Arnold | D39: Male | E39: 36 | F39: Amazon | G39: 45787 | H39: 46061 | J39: Mumbai | K39: Grocery | L39: P2750 | M39: Sunflower Oil | N39: Fortune | O39: 1 | P39: 7793 | Q39: 10301.16 | R39: 0 | S39: 10301.16 | T39: 2508.16 | U39: COD | V39: Cancelled | W39: 4 | X39: Mumbai Hub | Y39: Jessica Lewis
A40: ORD100038 | B40: CUST10038 | C40: Louis Johnston | D40: Female | E40: 27 | F40: Flipkart | G40: 45902 | H40: 45763 | I40: Delhi | J40: New Delhi | K40: Electronics | L40: P5210 | M40: Galaxy S24 | N40: Samsung | O40: 4 | P40: 2289 | Q40: 3275.78 | R40: 5 | S40: 12447.96 | T40: 3947.12 | U40: Debit Card | V40: Delivered | W40: 3 | X40: New Delhi Hub | Y40: James Alexander
A41: ORD100039 | B41: CUST10039 | C41: Nicole Mckenzie | D41: Male | E41: 26 | F41: Flipkart | G41: 46037 | H41: 45476 | I41: Karnataka | J41: Bengaluru | K41: Beauty | L41: P7944 | M41: Face Wash | N41: Loreal | O41: 5 | P41: 7115 | Q41: 7914.96 | R41: 0 | S41: 39574.8 | T41: 3999.8 | U41: UPI | V41: In Transit | W41: 3 | X41: Bengaluru Hub | Y41: Sarah Robinson
A42: ORD100040 | B42: CUST10040 | C42: Alexis Richardson | D42: Female | E42: 58 | F42: Amazon | G42: 45876 | H42: 45975 | I42: Maharashtra | J42: Pune | K42: Electronics | L42: P7018 | M42: iPhone 15 | N42: Apple | O42: 2 | P42: 25274 | Q42: 36619.98 | R42: 15 | S42: 62253.97 | T42: 22691.96 | U42: Credit Card | V42: Returned | W42: 5 | X42: Pune Hub | Y42: Patricia Gardner
A43: ORD100041 | B43: CUST10041 | C43: Jennifer Edwards | D43: Female | E43: 21 | F43: Flipkart | G43: 45859 | H43: 45904 | I43: Telangana | J43: Hyderabad | K43: Fashion | L43: P4859 | M43: Air Max Shoes | N43: Nike | O43: 4 | P43: 18988 | Q43: 21837.44 | R43: 15 | S43: 74247.3 | T43: 11397.76 | U43: COD | V43: Delivered | W43: 5 | X43: Hyderabad Hub | Y43: Alexa Wiley
A44: ORD100042 | B44: CUST10042 | C44: Russell Monroe | D44: Female | E44: 37 | F44: Amazon | G44: 46027 | H44: 45597 | I44: Delhi | J44: New Delhi | K44: Home | L44: P5990 | M44: Pressure Cooker | N44: Prestige | O44: 4 | P44: 20396 | Q44: 26976.2 | R44: 0 | S44: 107904.8 | T44: 26320.8 | U44: Debit Card | V44: In Transit | W44: 4 | X44: New Delhi Hub | Y44: Dr. Brian Miller
A45: ORD100043 | B45: CUST10043 | C45: Sara Weaver | D45: Male | E45: 57 | F45: Flipkart | G45: 46129 | H45: 45929 | I45: Maharashtra | J45: Pune | K45: Electronics | L45: P5182 | M45: Galaxy S24 | N45: Samsung | O45: 3 | P45: 2760 | Q45: 3800.52 | R45: 0 | S45: 11401.56 | T45: 3121.56 | U45: COD | V45: Returned | W45: 3 | X45: Pune Hub | Y45: Charles Fitzgerald
A46: ORD100044 | B46: CUST10044 | C46: Eric Harris | D46: Male | E46: 55 | F46: Amazon | G46: 45924 | H46: 45940 | I46: Delhi | J46: New Delhi | K46: Electronics | L46: P6167 | M46: Galaxy S24 | N46: Samsung | O46: 4 | P46: 16611 | Q46: 18707.32 | R46: 5 | S46: 71087.82 | T46: 8385.28 | U46: UPI | V46: Cancelled | W46: 1 | X46: New Delhi Hub | Y46: Richard Schaefer
A47: ORD100045 | B47: CUST10045 | C47: Amanda Elliott | D47: Female | E47: 54 | F47: Flipkart | G47: 46093 | H47: 45902 | I47: Delhi | J47: New Delhi | K47: Electronics | L47: P7269 | M47: Galaxy S24 | N47: Samsung | O47: 3 | P47: 29223 | Q47: 38901.68 | R47: 5 | S47: 110869.79 | T47: 29036.04 | U47: COD | V47: Delivered | W47: 1 | X47: New Delhi Hub | Y47: Benjamin Mora
A48: ORD100046 | B48: CUST10046 | C48: Annette Payne | D48: Male | E48: 42 | F48: Flipkart | G48: 46144 | H48: 45907 | I48: maharashtra | J48: Chennai | K48: electronics | L48: P5807 | N48: Prestige | O48: 5 | P48: 20367 | Q48: 25753.96 | R48: 15 | S48: 109454.33 | T48: 26934.8 | U48: UPI | V48: Delivered | W48: 5 | X48: Chennai Hub | Y48: Nicole Torres
A49: ORD100047 | B49: CUST10047 | C49: Aaron Clark MD | D49: Female | E49: 57 | F49: Flipkart | G49: 45707 | H49: 46002 | I49: Delhi | J49: New Delhi | K49: electronics | L49: P5991 | M49: Face Wash | N49: Loreal | O49: 2 | P49: 5958 | Q49: 6718.88 | R49: 20 | S49: 10750.21 | T49: 1521.76 | U49: Debit Card | V49: Cancelled | W49: 3 | X49: New Delhi Hub | Y49: Marvin Floyd
A50: ORD100048 | B50: CUST10048 | C50: Daniel Nichols | D50: Male | E50: 18 | F50: Flipkart | G50: 45683 | H50: 46170 | I50: Maharashtra | J50: Pune | K50: Beauty | L50: P5731 | M50: Face Wash | N50: Loreal | O50: 5 | P50: 29365 | Q50: 38587.11 | R50: 10 | S50: 173641.99 | T50: 46110.55 | U50: Credit Card | V50: Delivered | W50: 2 | X50: Pune Hub | Y50: Andrea Wolfe
A51: ORD100049 | B51: CUST10049 | C51: Cody Singh | D51: Male | E51: 60 | F51: Amazon | G51: 45772 | H51: 45532 | I51: Telangana | J51: Hyderabad | K51: Electronics | L51: P2525 | M51: Galaxy S24 | N51: Samsung | O51: 1 | P51: 21589 | Q51: 26488.47 | R51: 10 | S51: 23839.62 | T51: 4899.47 | U51: Debit Card | V51: Cancelled | W51: 3 | X51: Hyderabad Hub | Y51: Vickie Turner
A52: ORD100050 | B52: CUST10050 | C52: Jennifer Welch | D52: Male | E52: 24 | F52: Amazon | G52: 45811 | H52: 45533 | J52: Chennai | K52: Electronics | L52: P2909 | N52: Apple | O52: 2 | P52: 20982 | Q52: 27502.55 | R52: 10 | S52: 49504.59 | T52: 13041.1 | U52: COD | V52: Delivered | W52: 2 | X52: Chennai Hub | Y52: Elizabeth Moore
A53: ORD100051 | B53: CUST10051 | C53: Dan Lewis | D53: Female | E53: 36 | F53: Flipkart | G53: 45997 | H53: 45503 | I53: Telangana | J53: Hyderabad | K53: Home | L53: P1231 | M53: Pressure Cooker | N53: Prestige | O53: 5 | P53: 15977 | Q53: 21699.83 | R53: 15 | S53: 92224.28 | T53: 28614.15 | U53: Credit Card | V53: In Transit | W53: 3 | X53: Hyderabad Hub | Y53: Veronica Mays
A54: ORD100052 | B54: CUST10052 | C54: Rachel Weber | D54: Male | E54: 57 | F54: Amazon | G54: 46139 | H54: 45760 | I54: Maharashtra | J54: Pune | K54: Fashion | L54: P4664 | M54: Air Max Shoes | N54: Nike | O54: 1 | P54: 28567 | Q54: 38920.04 | R54: 15 | S54: 33082.03 | T54: 10353.04 | U54: UPI | V54: Delivered | W54: 2 | X54: Pune Hub | Y54: Cynthia Schwartz
A55: ORD100053 | B55: CUST10053 | C55: Henry Graves | D55: Male | E55: 43 | F55: Amazon | G55: 46026 | H55: 45490 | I55: Tamil Nadu | J55: Chennai | K55: Grocery | L55: P3946 | M55: Sunflower Oil | N55: Fortune | O55: 5 | P55: 4075 | Q55: 5183.29 | R55: 0 | S55: 25916.45 | T55: 5541.45 | U55: Credit Card | V55: Returned | W55: 3 | X55: Chennai Hub | Y55: Pamela White MD
A56: ORD100054 | B56: CUST10054 | C56: Angela Owen | D56: Male | E56: 56 | F56: Amazon | G56: 45917 | H56: 45866 | I56: Maharashtra | J56: Pune | K56: Fashion | L56: P4171 | M56: Air Max Shoes | N56: Nike | O56: 3 | P56: 10999 | Q56: 13707.58 | R56: 10 | S56: 37010.47 | T56: 8125.74 | U56: UPI | V56: Returned | W56: 3 | X56: Pune Hub | Y56: Nancy Martinez
A57: ORD100055 | B57: CUST10055 | C57: Garrett Garcia | D57: Male | E57: 41 | F57: Flipkart | G57: 45795 | H57: 45638 | I57: Telangana | J57: Hyderabad | K57: Electronics | L57: P9891 | M57: iPhone 15 | N57: Apple | O57: 4 | P57: 29239 | Q57: 37702.11 | R57: 20 | S57: 120646.75 | T57: 33852.44 | U57: COD | V57: In Transit | W57: 3 | X57: Hyderabad Hub | Y57: Julie Brown
A58: ORD100056 | B58: CUST10056 | C58: Danielle Smith | D58: Female | E58: 30 | F58: Amazon | G58: 46039 | H58: 45587 | I58: Delhi | J58: New Delhi | K58: Grocery | L58: P7484 | M58: Sunflower Oil | N58: Fortune | O58: 4 | P58: 22526 | Q58: 25803.23 | R58: 0 | S58: 103212.92 | T58: 13108.92 | U58: Credit Card | V58: Delivered | W58: 5 | X58: New Delhi Hub | Y58: James Lynch
A59: ORD100057 | B59: CUST10057 | C59: Ana Willis | D59: Male | E59: 32 | F59: Amazon | G59: 45923 | H59: 46053 | I59: Delhi | J59: New Delhi | K59: Electronics | L59: P1584 | M59: Galaxy S24 | N59: Samsung | O59: 3 | P59: 20408 | Q59: 25911.99 | R59: 20 | S59: 62188.78 | T59: 16511.97 | U59: UPI | V59: Delivered | W59: 4 | X59: New Delhi Hub | Y59: Paul Sanchez
A60: ORD100058 | B60: CUST10058 | C60: Briana Nguyen | D60: Female | E60: 35 | F60: Flipkart | G60: 45925 | H60: 45601 | I60: Tamil Nadu | J60: Chennai | K60: Grocery | L60: P1067 | M60: Sunflower Oil | N60: Fortune | O60: 3 | P60: 15427 | Q60: 22409.45 | R60: 20 | S60: 53782.68 | T60: 20947.35 | U60: Credit Card | V60: Delivered | X60: Chennai Hub | Y60: Michaela Huffman
A61: ORD100059 | B61: CUST10059 | C61: Theresa Spence | D61: Female | E61: 39 | F61: Amazon | G61: 46017 | H61: 46156 | I61: Tamil Nadu | J61: Chennai | K61: Fashion | L61: P1165 | M61: Air Max Shoes | N61: Nike | O61: 4 | P61: 7700 | Q61: 10108.3 | R61: 5 | S61: 38411.54 | T61: 9633.2 | U61: Credit Card | V61: Cancelled | W61: 3 | X61: Chennai Hub | Y61: Jonathan Vasquez MD
A62: ORD100060 | B62: CUST10060 | C62: Ashley Mann | D62: Female | E62: 41 | F62: Flipkart | G62: 46158 | H62: 45785 | I62: Karnataka | J62: Bengaluru | K62: Electronics | L62: P3831 | M62: Galaxy S24 | N62: Samsung | O62: 2 | P62: 21776 | Q62: 32410.34 | R62: 0 | S62: 64820.68 | T62: 21268.68 | U62: COD | V62: Cancelled | W62: 1 | X62: Bengaluru Hub | Y62: James Wells
A63: ORD100061 | B63: CUST10061 | C63: Vincent Anderson | D63: Female | E63: 31 | F63: Amazon | G63: 46026 | H63: 45677 | I63: Telangana | J63: Hyderabad | K63: Electronics | L63: P3580 | M63: iPhone 15 | N63: Apple | O63: 1 | P63: 8685 | Q63: 9884.19 | R63: 0 | S63: 9884.19 | T63: 1199.19 | U63: Debit Card | V63: Cancelled | W63: 2 | X63: Hyderabad Hub | Y63: Mary Nichols
A64: ORD100062 | B64: CUST10062 | C64: Jennifer Simpson | D64: Female | E64: 36 | F64: Flipkart | G64: 45492 | H64: 45496 | I64: Karnataka | J64: Bengaluru | K64: Fashion | L64: P1951 | M64: Air Max Shoes | N64: Nike | O64: 2 | P64: 19331 | Q64: 25103.5 | R64: 10 | S64: 45186.3 | T64: 11545 | U64: UPI | V64: Cancelled | W64: 5 | X64: Bengaluru Hub | Y64: Melanie Garrett
...

Sheet Raw_Data

Sheet Cleaned_Data
A1: Order_ID | B1: Customer_ID | C1: Customer_Name | D1: Gender | E1: Age | F1: Platform | G1: Order_Date | H1: Delivery_Date | I1: State | J1: City | K1: Category | L1: Product_ID | M1: Product_Name | N1: Brand | O1: Quantity | P1: Cost_Price | Q1: Selling_Price | R1: Discount_% | S1: Sales | T1: Profit | U1: Payment_Method | V1: Delivery_Status | W1: Customer_Rating | X1: Warehouse | Y1: Salesperson | Z1: Customer_Name2 | AA1: State3 | AB1: City4 | AC1: Category5 | AD1: Product_Name6 | AE1: Brand7 | AF1: Warehouse8 | AG1: Salesperson9
A2: ORD100000 | B2: CUST10000 | C2: Ashley Cox | D2: Female | E2: 35 | F2: Flipkart | G2: 45988 | H2: 46078 | I2: Maharashtra | J2: Mumbai | K2: Home | L2: P4053 | M2: Pressure Cooker | N2: Prestige | O2: 1 | P2: 17415 | Q2: 19836.65 | R2: 20 | S2: 15869.32 | T2: 2421.65 | U2: Debit Card | V2: Cancelled | W2: 1 | X2: Mumbai Hub | Y2: Robin Hodges | Z2: =TRIM(C2) -> Ashley Cox | AA2: =TRIM(I2) -> Maharashtra | AB2: =TRIM(J2) -> Mumbai | AC2: =TRIM(K2) -> Home | AD2: =TRIM(M2) -> Pressure Cooker | AE2: =TRIM(N2) -> Prestige | AF2: =TRIM(X2) -> Mumbai Hub | AG2: =TRIM(Y2) -> Robin Hodges
A3: ORD100001 | B3: CUST10001 | C3: Rebecca Everett | D3: Female | E3: 41 | F3: Flipkart | G3: 45843 | H3: 45577 | I3: Maharashtra | J3: Pune | K3: Grocery | L3: P3274 | M3: Sunflower Oil | N3: Fortune | O3: 4 | P3: 13107 | Q3: 17607.4 | R3: 10 | S3: 63386.64 | T3: 18001.6 | U3: UPI | V3: Cancelled | W3: 2 | X3: Pune Hub | Y3: Austin Mann | Z3: =TRIM(C3) -> Rebecca Everett | AA3: =TRIM(I3) -> Maharashtra | AB3: =TRIM(J3) -> Pune | AC3: =TRIM(K3) -> Grocery | AD3: =TRIM(M3) -> Sunflower Oil | AE3: =TRIM(N3) -> Fortune | AF3: =TRIM(X3) -> Pune Hub | AG3: =TRIM(Y3) -> Austin Mann
A4: ORD100002 | B4: CUST10002 | C4: Jacob Dalton | D4: Male | E4: 22 | F4: Flipkart | G4: 45879 | H4: 45906 | I4: Delhi | J4: New Delhi | K4: Grocery | L4: P1312 | M4: Sunflower Oil | N4: Fortune | O4: 1 | P4: 1905 | Q4: 2290.68 | R4: 15 | S4: 1947.08 | T4: 385.68 | U4: Debit Card | V4: Cancelled | W4: 4 | X4: New Delhi Hub | Y4: Andres Wright | Z4: =TRIM(C4) -> Jacob Dalton | AA4: =TRIM(I4) -> Delhi | AB4: =TRIM(J4) -> New Delhi | AC4: =TRIM(K4) -> Grocery | AD4: =TRIM(M4) -> Sunflower Oil | AE4: =TRIM(N4) -> Fortune | AF4: =TRIM(X4) -> New Delhi Hub | AG4: =TRIM(Y4) -> Andres Wright
A5: ORD100003 | B5: CUST10003 | C5: Diana Murphy DDS | D5: Male | E5: 59 | F5: Flipkart | G5: 45608 | H5: 45927 | I5: Telangana | J5: Hyderabad | K5: Beauty | L5: P3240 | M5: Face Wash | N5: Loreal | O5: 3 | P5: 10574 | Q5: 11718.4 | R5: 20 | S5: 28124.16 | T5: 3433.2 | U5: Debit Card | V5: Delivered | W5: 2 | X5: Hyderabad Hub | Y5: Eugene Martin | Z5: =TRIM(C5) -> Diana Murphy DDS | AA5: =TRIM(I5) -> Telangana | AB5: =TRIM(J5) -> Hyderabad | AC5: =TRIM(K5) -> Beauty | AD5: =TRIM(M5) -> Face Wash | AE5: =TRIM(N5) -> Loreal | AF5: =TRIM(X5) -> Hyderabad Hub | AG5: =TRIM(Y5) -> Eugene Martin
A6: ORD100004 | B6: CUST10004 | C6: Henry Rojas | D6: Female | E6: 55 | F6: Flipkart | G6: 45558 | H6: 45575 | I6: Karnataka | J6: Bengaluru | K6: Beauty | L6: P5574 | M6: Face Wash | N6: Loreal | O6: 5 | P6: 19031 | Q6: 27531.63 | R6: 15 | S6: 117009.43 | T6: 42503.15 | U6: Credit Card | V6: Delivered | W6: 4 | X6: Bengaluru Hub | Y6: Amy Contreras | Z6: =TRIM(C6) -> Henry Rojas | AA6: =TRIM(I6) -> Karnataka | AB6: =TRIM(J6) -> Bengaluru | AC6: =TRIM(K6) -> Beauty | AD6: =TRIM(M6) -> Face Wash | AE6: =TRIM(N6) -> Loreal | AF6: =TRIM(X6) -> Bengaluru Hub | AG6: =TRIM(Y6) -> Amy Contreras
A7: ORD100005 | B7: CUST10005 | C7: Morgan Robinson | D7: Male | E7: 48 | F7: Flipkart | G7: 46027 | H7: 45728 | I7: Tamil Nadu | J7: Chennai | K7: Grocery | L7: P3562 | M7: Sunflower Oil | N7: Fortune | O7: 4 | P7: 7382 | Q7: 9091.91 | R7: 5 | S7: 34549.26 | T7: 6839.64 | U7: UPI | V7: Delivered | W7: 1 | X7: Chennai Hub | Y7: Mckenzie Brady | Z7: =TRIM(C7) -> Morgan Robinson | AA7: =TRIM(I7) -> Tamil Nadu | AB7: =TRIM(J7) -> Chennai | AC7: =TRIM(K7) -> Grocery | AD7: =TRIM(M7) -> Sunflower Oil | AE7: =TRIM(N7) -> Fortune | AF7: =TRIM(X7) -> Chennai Hub | AG7: =TRIM(Y7) -> Mckenzie Brady
A8: ORD100006 | B8: CUST10006 | C8: Robert Peterson | D8: Female | E8: 32 | F8: Amazon | G8: 45610 | H8: 46130 | I8: Telangana | J8: Hyderabad | K8: Electronics | L8: P2671 | M8: Galaxy S24 | N8: Samsung | O8: 2 | P8: 26006 | Q8: 29271.93 | R8: 0 | S8: 58543.86 | T8: 6531.86 | U8: Debit Card | V8: Cancelled | W8: 5 | X8: Hyderabad Hub | Y8: Michele Taylor | Z8: =TRIM(C8) -> Robert Peterson | AA8: =TRIM(I8) -> Telangana | AB8: =TRIM(J8) -> Hyderabad | AC8: =TRIM(K8) -> Electronics | AD8: =TRIM(M8) -> Galaxy S24 | AE8: =TRIM(N8) -> Samsung | AF8: =TRIM(X8) -> Hyderabad Hub | AG8: =TRIM(Y8) -> Michele Taylor
A9: ORD100007 | B9: CUST10007 | C9: Lindsey Brown | D9: Male | E9: 54 | F9: Flipkart | G9: 45708 | H9: 45634 | I9: Karnataka | J9: Bengaluru | K9: Beauty | L9: P3840 | M9: Face Wash | N9: Loreal | O9: 3 | P9: 9411 | Q9: 12520.75 | R9: 15 | S9: 31927.91 | T9: 9329.25 | U9: Debit Card | V9: Delivered | W9: 2 | X9: Bengaluru Hub | Y9: Christina Stevens | Z9: =TRIM(C9) -> Lindsey Brown | AA9: =TRIM(I9) -> Karnataka | AB9: =TRIM(J9) -> Bengaluru | AC9: =TRIM(K9) -> Beauty | AD9: =TRIM(M9) -> Face Wash | AE9: =TRIM(N9) -> Loreal | AF9: =TRIM(X9) -> Bengaluru Hub | AG9: =TRIM(Y9) -> Christina Stevens
A10: ORD100008 | B10: CUST10008 | C10: Charlotte Gilbert | D10: Female | E10: 46 | F10: Flipkart | G10: 45611 | H10: 45792 | I10: Maharashtra | J10: Mumbai | K10: Grocery | L10: P5256 | M10: Sunflower Oil | N10: Fortune | O10: 3 | P10: 18006 | Q10: 20107.58 | R10: 10 | S10: 54290.47 | T10: 6304.74 | U10: Debit Card | V10: Cancelled | W10: 3 | X10: Mumbai Hub | Y10: Clifford Newton | Z10: =TRIM(C10) -> Charlotte Gilbert | AA10: =TRIM(I10) -> Maharashtra | AB10: =TRIM(J10) -> Mumbai | AC10: =TRIM(K10) -> Grocery | AD10: =TRIM(M10) -> Sunflower Oil | AE10: =TRIM(N10) -> Fortune | AF10: =TRIM(X10) -> Mumbai Hub | AG10: =TRIM(Y10) -> Clifford Newton
A11: ORD100009 | B11: CUST10009 | C11: Rachel Garcia | D11: Male | E11: 32 | F11: Flipkart | G11: 46067 | H11: 45805 | I11: Karnataka | J11: Bengaluru | K11: Beauty | L11: P3816 | M11: Face Wash | N11: Loreal | O11: 2 | P11: 2839 | Q11: 3511.61 | R11: 20 | S11: 5618.58 | T11: 1345.22 | U11: Credit Card | V11: In Transit | W11: 4 | X11: Bengaluru Hub | Y11: Jerome Campbell | Z11: =TRIM(C11) -> Rachel Garcia | AA11: =TRIM(I11) -> Karnataka | AB11: =TRIM(J11) -> Bengaluru | AC11: =TRIM(K11) -> Beauty | AD11: =TRIM(M11) -> Face Wash | AE11: =TRIM(N11) -> Loreal | AF11: =TRIM(X11) -> Bengaluru Hub | AG11: =TRIM(Y11) -> Jerome Campbell
A12: ORD100010 | B12: CUST10010 | C12: Travis Keller | D12: Female | E12: 46 | F12: Amazon | G12: 46069 | H12: 45474 | I12: Delhi | J12: New Delhi | K12: Fashion | L12: P2051 | M12: Air Max Shoes | N12: Nike | O12: 5 | P12: 15167 | Q12: 19780.36 | R12: 5 | S12: 93956.71 | T12: 23066.8 | U12: UPI | V12: Delivered | W12: 1 | X12: New Delhi Hub | Y12: Anthony Day | Z12: =TRIM(C12) -> Travis Keller | AA12: =TRIM(I12) -> Delhi | AB12: =TRIM(J12) -> New Delhi | AC12: =TRIM(K12) -> Fashion | AD12: =TRIM(M12) -> Air Max Shoes | AE12: =TRIM(N12) -> Nike | AF12: =TRIM(X12) -> New Delhi Hub | AG12: =TRIM(Y12) -> Anthony Day
A13: ORD100011 | B13: CUST10011 | C13: Joshua Thompson | D13: Female | E13: 19 | F13: Flipkart | G13: 45854 | H13: 45561 | I13: Telangana | J13: Hyderabad | K13: Fashion | L13: P5949 | M13: Air Max Shoes | N13: Nike | O13: 4 | P13: 12428 | Q13: 15530.69 | R13: 0 | S13: 62122.76 | T13: 12410.76 | U13: COD | V13: Delivered | W13: 3 | X13: Hyderabad Hub | Y13: Devin Johnson | Z13: =TRIM(C13) -> Joshua Thompson | AA13: =TRIM(I13) -> Telangana | AB13: =TRIM(J13) -> Hyderabad | AC13: =TRIM(K13) -> Fashion | AD13: =TRIM(M13) -> Air Max Shoes | AE13: =TRIM(N13) -> Nike | AF13: =TRIM(X13) -> Hyderabad Hub | AG13: =TRIM(Y13) -> Devin Johnson
... A38: ORD100036 | B38: CUST10036 | C38: Sheila Townsend | D38: Female | E38: 49 | F38: Flipkart | G38: 46181 | H38: 45658 | I38: Tamil Nadu | J38: Chennai | K38: Fashion | L38: P1779 | M38: Air Max Shoes | N38: Nike | O38: 1 | P38: 26287 | Q38: 37421.5 | R38: 20 | S38: 29937.2 | T38: 11134.5 | U38: Debit Card | V38: In Transit | W38: 5 | X38: Chennai Hub | Y38: Kenneth Jackson | Z38: =TRIM(C38) -> Sheila Townsend | AA38: =TRIM(I38) -> Tamil Nadu | AB38: =TRIM(J38) -> Chennai | AC38: =TRIM(K38) -> Fashion | AD38: =TRIM(M38) -> Air Max Shoes | AE38: =TRIM(N38) -> Nike | AF38: =TRIM(X38) -> Chennai Hub | AG38: =TRIM(Y38) -> Kenneth Jackson
A39: ORD100037 | B39: CUST10037 | C39: Garrett Arnold | D39: Male | E39: 36 | F39: Amazon | G39: 45787 | H39: 46061 | J39: Mumbai | K39: Grocery | L39: P2750 | M39: Sunflower Oil | N39: Fortune | O39: 1 | P39: 7793 | Q39: 10301.16 | R39: 0 | S39: 10301.16 | T39: 2508.16 | U39: COD | V39: Cancelled | W39: 4 | X39: Mumbai Hub | Y39: Jessica Lewis | Z39: =TRIM(C39) -> Garrett Arnold | AA39: Maharashtra | AB39: =TRIM(J39) -> Mumbai | AC39: =TRIM(K39) -> Grocery | AD39: =TRIM(M39) -> Sunflower Oil | AE39: =TRIM(N39) -> Fortune | AF39: =TRIM(X39) -> Mumbai Hub | AG39: =TRIM(Y39) -> Jessica Lewis
A40: ORD100038 | B40: CUST10038 | C40: Louis Johnston | D40: Female | E40: 27 | F40: Flipkart | G40: 45902 | H40: 45763 | I40: Delhi | J40: New Delhi | K40: Electronics | L40: P5210 | M40: Galaxy S24 | N40: Samsung | O40: 4 | P40: 2289 | Q40: 3275.78 | R40: 5 | S40: 12447.96 | T40: 3947.12 | U40: Debit Card | V40: Delivered | W40: 3 | X40: New Delhi Hub | Y40: James Alexander | Z40: =TRIM(C40) -> Louis Johnston | AA40: =TRIM(I40) -> Delhi | AB40: =TRIM(J40) -> New Delhi | AC40: =TRIM(K40) -> Electronics | AD40: =TRIM(M40) -> Galaxy S24 | AE40: =TRIM(N40) -> Samsung | AF40: =TRIM(X40) -> New Delhi Hub | AG40: =TRIM(Y40) -> James Alexander
A41: ORD100039 | B41: CUST10039 | C41: Nicole Mckenzie | D41: Male | E41: 26 | F41: Flipkart | G41: 46037 | H41: 45476 | I41: Karnataka | J41: Bengaluru | K41: Beauty | L41: P7944 | M41: Face Wash | N41: Loreal | O41: 5 | P41: 7115 | Q41: 7914.96 | R41: 0 | S41: 39574.8 | T41: 3999.8 | U41: UPI | V41: In Transit | W41: 3 | X41: Bengaluru Hub | Y41: Sarah Robinson | Z41: =TRIM(C41) -> Nicole Mckenzie | AA41: =TRIM(I41) -> Karnataka | AB41: =TRIM(J41) -> Bengaluru | AC41: =TRIM(K41) -> Beauty | AD41: =TRIM(M41) -> Face Wash | AE41: =TRIM(N41) -> Loreal | AF41: =TRIM(X41) -> Bengaluru Hub | AG41: =TRIM(Y41) -> Sarah Robinson
A42: ORD100040 | B42: CUST10040 | C42: Alexis Richardson | D42: Female | E42: 58 | F42: Amazon | G42: 45876 | H42: 45975 | I42: Maharashtra | J42: Pune | K42: Electronics | L42: P7018 | M42: iPhone 15 | N42: Apple | O42: 2 | P42: 25274 | Q42: 36619.98 | R42: 15 | S42: 62253.97 | T42: 22691.96 | U42: Credit Card | V42: Returned | W42: 5 | X42: Pune Hub | Y42: Patricia Gardner | Z42: =TRIM(C42) -> Alexis Richardson | AA42: =TRIM(I42) -> Maharashtra | AB42: =TRIM(J42) -> Pune | AC42: =TRIM(K42) -> Electronics | AD42: =TRIM(M42) -> iPhone 15 | AE42: =TRIM(N42) -> Apple | AF42: =TRIM(X42) -> Pune Hub | AG42: =TRIM(Y42) -> Patricia Gardner
A43: ORD100041 | B43: CUST10041 | C43: Jennifer Edwards | D43: Female | E43: 21 | F43: Flipkart | G43: 45859 | H43: 45904 | I43: Telangana | J43: Hyderabad | K43: Fashion | L43: P4859 | M43: Air Max Shoes | N43: Nike | O43: 4 | P43: 18988 | Q43: 21837.44 | R43: 15 | S43: 74247.3 | T43: 11397.76 | U43: COD | V43: Delivered | W43: 5 | X43: Hyderabad Hub | Y43: Alexa Wiley | Z43: =TRIM(C43) -> Jennifer Edwards | AA43: =TRIM(I43) -> Telangana | AB43: =TRIM(J43) -> Hyderabad | AC43: =TRIM(K43) -> Fashion | AD43: =TRIM(M43) -> Air Max Shoes | AE43: =TRIM(N43) -> Nike | AF43: =TRIM(X43) -> Hyderabad Hub | AG43: =TRIM(Y43) -> Alexa Wiley
A44: ORD100042 | B44: CUST10042 | C44: Russell Monroe | D44: Female | E44: 37 | F44: Amazon | G44: 46027 | H44: 45597 | I44: Delhi | J44: New Delhi | K44: Home | L44: P5990 | M44: Pressure Cooker | N44: Prestige | O44: 4 | P44: 20396 | Q44: 26976.2 | R44: 0 | S44: 107904.8 | T44: 26320.8 | U44: Debit Card | V44: In Transit | W44: 4 | X44: New Delhi Hub | Y44: Dr. Brian Miller | Z44: =TRIM(C44) -> Russell Monroe | AA44: =TRIM(I44) -> Delhi | AB44: =TRIM(J44) -> New Delhi | AC44: =TRIM(K44) -> Home | AD44: =TRIM(M44) -> Pressure Cooker | AE44: =TRIM(N44) -> Prestige | AF44: =TRIM(X44) -> New Delhi Hub | AG44: =TRIM(Y44) -> Dr. Brian Miller
A45: ORD100043 | B45: CUST10043 | C45: Sara Weaver | D45: Male | E45: 57 | F45: Flipkart | G45: 46129 | H45: 45929 | I45: Maharashtra | J45: Pune | K45: Electronics | L45: P5182 | M45: Galaxy S24 | N45: Samsung | O45: 3 | P45: 2760 | Q45: 3800.52 | R45: 0 | S45: 11401.56 | T45: 3121.56 | U45: COD | V45: Returned | W45: 3 | X45: Pune Hub | Y45: Charles Fitzgerald | Z45: =TRIM(C45) -> Sara Weaver | AA45: =TRIM(I45) -> Maharashtra | AB45: =TRIM(J45) -> Pune | AC45: =TRIM(K45) -> Electronics | AD45: =TRIM(M45) -> Galaxy S24 | AE45: =TRIM(N45) -> Samsung | AF45: =TRIM(X45) -> Pune Hub | AG45: =TRIM(Y45) -> Charles Fitzgerald
A46: ORD100044 | B46: CUST10044 | C46: Eric Harris | D46: Male | E46: 55 | F46: Amazon | G46: 45924 | H46: 45940 | I46: Delhi | J46: New Delhi | K46: Electronics | L46: P6167 | M46: Galaxy S24 | N46: Samsung | O46: 4 | P46: 16611 | Q46: 18707.32 | R46: 5 | S46: 71087.82 | T46: 8385.28 | U46: UPI | V46: Cancelled | W46: 1 | X46: New Delhi Hub | Y46: Richard Schaefer | Z46: =TRIM(C46) -> Eric Harris | AA46: =TRIM(I46) -> Delhi | AB46: =TRIM(J46) -> New Delhi | AC46: =TRIM(K46) -> Electronics | AD46: =TRIM(M46) -> Galaxy S24 | AE46: =TRIM(N46) -> Samsung | AF46: =TRIM(X46) -> New Delhi Hub | AG46: =TRIM(Y46) -> Richard Schaefer
A47: ORD100045 | B47: CUST10045 | C47: Amanda Elliott | D47: Female | E47: 54 | F47: Flipkart | G47: 46093 | H47: 45902 | I47: Delhi | J47: New Delhi | K47: Electronics | L47: P7269 | M47: Galaxy S24 | N47: Samsung | O47: 3 | P47: 29223 | Q47: 38901.68 | R47: 5 | S47: 110869.79 | T47: 29036.04 | U47: COD | V47: Delivered | W47: 1 | X47: New Delhi Hub | Y47: Benjamin Mora | Z47: =TRIM(C47) -> Amanda Elliott | AA47: =TRIM(I47) -> Delhi | AB47: =TRIM(J47) -> New Delhi | AC47: =TRIM(K47) -> Electronics | AD47: =TRIM(M47) -> Galaxy S24 | AE47: =TRIM(N47) -> Samsung | AF47: =TRIM(X47) -> New Delhi Hub | AG47: =TRIM(Y47) -> Benjamin Mora
A48: ORD100046 | B48: CUST10046 | C48: Annette Payne | D48: Male | E48: 42 | F48: Flipkart | G48: 46144 | H48: 45907 | I48: Maharashtra | J48: Chennai | K48: Electronics | L48: P5807 | N48: Prestige | O48: 5 | P48: 20367 | Q48: 25753.96 | R48: 15 | S48: 109454.33 | T48: 26934.8 | U48: UPI | V48: Delivered | W48: 5 | X48: Chennai Hub | Y48: Nicole Torres | Z48: =TRIM(C48) -> Annette Payne | AA48: =TRIM(I48) -> Maharashtra | AB48: =TRIM(J48) -> Chennai | AC48: =TRIM(K48) -> Electronics | AD48: Pressure Cooker | AE48: =TRIM(N48) -> Prestige | AF48: =TRIM(X48) -> Chennai Hub | AG48: =TRIM(Y48) -> Nicole Torres
A49: ORD100047 | B49: CUST10047 | C49: Aaron Clark MD | D49: Female | E49: 57 | F49: Flipkart | G49: 45707 | H49: 46002 | I49: Delhi | J49: New Delhi | K49: Electronics | L49: P5991 | M49: Face Wash | N49: Loreal | O49: 2 | P49: 5958 | Q49: 6718.88 | R49: 20 | S49: 10750.21 | T49: 1521.76 | U49: Debit Card | V49: Cancelled | W49: 3 | X49: New Delhi Hub | Y49: Marvin Floyd | Z49: =TRIM(C49) -> Aaron Clark MD | AA49: =TRIM(I49) -> Delhi | AB49: =TRIM(J49) -> New Delhi | AC49: =TRIM(K49) -> Electronics | AD49: =TRIM(M49) -> Face Wash | AE49: =TRIM(N49) -> Loreal | AF49: =TRIM(X49) -> New Delhi Hub | AG49: =TRIM(Y49) -> Marvin Floyd
A50: ORD100048 | B50: CUST10048 | C50: Daniel Nichols | D50: Male | E50: 18 | F50: Flipkart | G50: 45683 | H50: 46170 | I50: Maharashtra | J50: Pune | K50: Beauty | L50: P5731 | M50: Face Wash | N50: Loreal | O50: 5 | P50: 29365 | Q50: 38587.11 | R50: 10 | S50: 173641.99 | T50: 46110.55 | U50: Credit Card | V50: Delivered | W50: 2 | X50: Pune Hub | Y50: Andrea Wolfe | Z50: =TRIM(C50) -> Daniel Nichols | AA50: =TRIM(I50) -> Maharashtra | AB50: =TRIM(J50) -> Pune | AC50: =TRIM(K50) -> Beauty | AD50: =TRIM(M50) -> Face Wash | AE50: =TRIM(N50) -> Loreal | AF50: =TRIM(X50) -> Pune Hub | AG50: =TRIM(Y50) -> Andrea Wolfe
A51: ORD100049 | B51: CUST10049 | C51: Cody Singh | D51: Male | E51: 60 | F51: Amazon | G51: 45772 | H51: 45532 | I51: Telangana | J51: Hyderabad | K51: Electronics | L51: P2525 | M51: Galaxy S24 | N51: Samsung | O51: 1 | P51: 21589 | Q51: 26488.47 | R51: 10 | S51: 23839.62 | T51: 4899.47 | U51: Debit Card | V51: Cancelled | W51: 3 | X51: Hyderabad Hub | Y51: Vickie Turner | Z51: =TRIM(C51) -> Cody Singh | AA51: =TRIM(I51) -> Telangana | AB51: =TRIM(J51) -> Hyderabad | AC51: =TRIM(K51) -> Electronics | AD51: =TRIM(M51) -> Galaxy S24 | AE51: =TRIM(N51) -> Samsung | AF51: =TRIM(X51) -> Hyderabad Hub | AG51: =TRIM(Y51) -> Vickie Turner
A52: ORD100050 | B52: CUST10050 | C52: Jennifer Welch | D52: Male | E52: 24 | F52: Amazon | G52: 45811 | H52: 45533 | J52: Chennai | K52: Electronics | L52: P2909 | N52: Apple | O52: 2 | P52: 20982 | Q52: 27502.55 | R52: 10 | S52: 49504.59 | T52: 13041.1 | U52: COD | V52: Delivered | W52: 2 | X52: Chennai Hub | Y52: Elizabeth Moore | Z52: =TRIM(C52) -> Jennifer Welch | AA52: Tamil Nadu | AB52: =TRIM(J52) -> Chennai | AC52: =TRIM(K52) -> Electronics | AD52: iPhone 15 | AE52: =TRIM(N52) -> Apple | AF52: =TRIM(X52) -> Chennai Hub | AG52: =TRIM(Y52) -> Elizabeth Moore
A53: ORD100051 | B53: CUST10051 | C53: Dan Lewis | D53: Female | E53: 36 | F53: Flipkart | G53: 45997 | H53: 45503 | I53: Telangana | J53: Hyderabad | K53: Home | L53: P1231 | M53: Pressure Cooker | N53: Prestige | O53: 5 | P53: 15977 | Q53: 21699.83 | R53: 15 | S53: 92224.28 | T53: 28614.15 | U53: Credit Card | V53: In Transit | W53: 3 | X53: Hyderabad Hub | Y53: Veronica Mays | Z53: =TRIM(C53) -> Dan Lewis | AA53: =TRIM(I53) -> Telangana | AB53: =TRIM(J53) -> Hyderabad | AC53: =TRIM(K53) -> Home | AD53: =TRIM(M53) -> Pressure Cooker | AE53: =TRIM(N53) -> Prestige | AF53: =TRIM(X53) -> Hyderabad Hub | AG53: =TRIM(Y53) -> Veronica Mays
A54: ORD100052 | B54: CUST10052 | C54: Rachel Weber | D54: Male | E54: 57 | F54: Amazon | G54: 46139 | H54: 45760 | I54: Maharashtra | J54: Pune | K54: Fashion | L54: P4664 | M54: Air Max Shoes | N54: Nike | O54: 1 | P54: 28567 | Q54: 38920.04 | R54: 15 | S54: 33082.03 | T54: 10353.04 | U54: UPI | V54: Delivered | W54: 2 | X54: Pune Hub | Y54: Cynthia Schwartz | Z54: =TRIM(C54) -> Rachel Weber | AA54: =TRIM(I54) -> Maharashtra | AB54: =TRIM(J54) -> Pune | AC54: =TRIM(K54) -> Fashion | AD54: =TRIM(M54) -> Air Max Shoes | AE54: =TRIM(N54) -> Nike | AF54: =TRIM(X54) -> Pune Hub | AG54: =TRIM(Y54) -> Cynthia Schwartz
A55: ORD100053 | B55: CUST10053 | C55: Henry Graves | D55: Male | E55: 43 | F55: Amazon | G55: 46026 | H55: 45490 | I55: Tamil Nadu | J55: Chennai | K55: Grocery | L55: P3946 | M55: Sunflower Oil | N55: Fortune | O55: 5 | P55: 4075 | Q55: 5183.29 | R55: 0 | S55: 25916.45 | T55: 5541.45 | U55: Credit Card | V55: Returned | W55: 3 | X55: Chennai Hub | Y55: Pamela White MD | Z55: =TRIM(C55) -> Henry Graves | AA55: =TRIM(I55) -> Tamil Nadu | AB55: =TRIM(J55) -> Chennai | AC55: =TRIM(K55) -> Grocery | AD55: =TRIM(M55) -> Sunflower Oil | AE55: =TRIM(N55) -> Fortune | AF55: =TRIM(X55) -> Chennai Hub | AG55: =TRIM(Y55) -> Pamela White MD
A56: ORD100054 | B56: CUST10054 | C56: Angela Owen | D56: Male | E56: 56 | F56: Amazon | G56: 45917 | H56: 45866 | I56: Maharashtra | J56: Pune | K56: Fashion | L56: P4171 | M56: Air Max Shoes | N56: Nike | O56: 3 | P56: 10999 | Q56: 13707.58 | R56: 10 | S56: 37010.47 | T56: 8125.74 | U56: UPI | V56: Returned | W56: 3 | X56: Pune Hub | Y56: Nancy Martinez | Z56: =TRIM(C56) -> Angela Owen | AA56: =TRIM(I56) -> Maharashtra | AB56: =TRIM(J56) -> Pune | AC56: =TRIM(K56) -> Fashion | AD56: =TRIM(M56) -> Air Max Shoes | AE56: =TRIM(N56) -> Nike | AF56: =TRIM(X56) -> Pune Hub | AG56: =TRIM(Y56) -> Nancy Martinez
A57: ORD100055 | B57: CUST10055 | C57: Garrett Garcia | D57: Male | E57: 41 | F57: Flipkart | G57: 45795 | H57: 45638 | I57: Telangana | J57: Hyderabad | K57: Electronics | L57: P9891 | M57: iPhone 15 | N57: Apple | O57: 4 | P57: 29239 | Q57: 37702.11 | R57: 20 | S57: 120646.75 | T57: 33852.44 | U57: COD | V57: In Transit | W57: 3 | X57: Hyderabad Hub | Y57: Julie Brown | Z57: =TRIM(C57) -> Garrett Garcia | AA57: =TRIM(I57) -> Telangana | AB57: =TRIM(J57) -> Hyderabad | AC57: =TRIM(K57) -> Electronics | AD57: =TRIM(M57) -> iPhone 15 | AE57: =TRIM(N57) -> Apple | AF57: =TRIM(X57) -> Hyderabad Hub | AG57: =TRIM(Y57) -> Julie Brown
A58: ORD100056 | B58: CUST10056 | C58: Danielle Smith | D58: Female | E58: 30 | F58: Amazon | G58: 46039 | H58: 45587 | I58: Delhi | J58: New Delhi | K58: Grocery | L58: P7484 | M58: Sunflower Oil | N58: Fortune | O58: 4 | P58: 22526 | Q58: 25803.23 | R58: 0 | S58: 103212.92 | T58: 13108.92 | U58: Credit Card | V58: Delivered | W58: 5 | X58: New Delhi Hub | Y58: James Lynch | Z58: =TRIM(C58) -> Danielle Smith | AA58: =TRIM(I58) -> Delhi | AB58: =TRIM(J58) -> New Delhi | AC58: =TRIM(K58) -> Grocery | AD58: =TRIM(M58) -> Sunflower Oil | AE58: =TRIM(N58) -> Fortune | AF58: =TRIM(X58) -> New Delhi Hub | AG58: =TRIM(Y58) -> James Lynch
A59: ORD100057 | B59: CUST10057 | C59: Ana Willis | D59: Male | E59: 32 | F59: Amazon | G59: 45923 | H59: 46053 | I59: Delhi | J59: New Delhi | K59: Electronics | L59: P1584 | M59: Galaxy S24 | N59: Samsung | O59: 3 | P59: 20408 | Q59: 25911.99 | R59: 20 | S59: 62188.78 | T59: 16511.97 | U59: UPI | V59: Delivered | W59: 4 | X59: New Delhi Hub | Y59: Paul Sanchez | Z59: =TRIM(C59) -> Ana Willis | AA59: =TRIM(I59) -> Delhi | AB59: =TRIM(J59) -> New Delhi | AC59: =TRIM(K59) -> Electronics | AD59: =TRIM(M59) -> Galaxy S24 | AE59: =TRIM(N59) -> Samsung | AF59: =TRIM(X59) -> New Delhi Hub | AG59: =TRIM(Y59) -> Paul Sanchez
A60: ORD100058 | B60: CUST10058 | C60: Briana Nguyen | D60: Female | E60: 35 | F60: Flipkart | G60: 45925 | H60: 45601 | I60: Tamil Nadu | J60: Chennai | K60: Grocery | L60: P1067 | M60: Sunflower Oil | N60: Fortune | O60: 3 | P60: 15427 | Q60: 22409.45 | R60: 20 | S60: 53782.68 | T60: 20947.35 | U60: Credit Card | V60: Delivered | W60: 3 | X60: Chennai Hub | Y60: Michaela Huffman | Z60: =TRIM(C60) -> Briana Nguyen | AA60: =TRIM(I60) -> Tamil Nadu | AB60: =TRIM(J60) -> Chennai | AC60: =TRIM(K60) -> Grocery | AD60: =TRIM(M60) -> Sunflower Oil | AE60: =TRIM(N60) -> Fortune | AF60: =TRIM(X60) -> Chennai Hub | AG60: =TRIM(Y60) -> Michaela Huffman
A61: ORD100059 | B61: CUST10059 | C61: Theresa Spence | D61: Female | E61: 39 | F61: Amazon | G61: 46017 | H61: 46156 | I61: Tamil Nadu | J61: Chennai | K61: Fashion | L61: P1165 | M61: Air Max Shoes | N61: Nike | O61: 4 | P61: 7700 | Q61: 10108.3 | R61: 5 | S61: 38411.54 | T61: 9633.2 | U61: Credit Card | V61: Cancelled | W61: 3 | X61: Chennai Hub | Y61: Jonathan Vasquez MD | Z61: =TRIM(C61) -> Theresa Spence | AA61: =TRIM(I61) -> Tamil Nadu | AB61: =TRIM(J61) -> Chennai | AC61: =TRIM(K61) -> Fashion | AD61: =TRIM(M61) -> Air Max Shoes | AE61: =TRIM(N61) -> Nike | AF61: =TRIM(X61) -> Chennai Hub | AG61: =TRIM(Y61) -> Jonathan Vasquez MD
A62: ORD100060 | B62: CUST10060 | C62: Ashley Mann | D62: Female | E62: 41 | F62: Flipkart | G62: 46158 | H62: 45785 | I62: Karnataka | J62: Bengaluru | K62: Electronics | L62: P3831 | M62: Galaxy S24 | N62: Samsung | O62: 2 | P62: 21776 | Q62: 32410.34 | R62: 0 | S62: 64820.68 | T62: 21268.68 | U62: COD | V62: Cancelled | W62: 1 | X62: Bengaluru Hub | Y62: James Wells | Z62: =TRIM(C62) -> Ashley Mann | AA62: =TRIM(I62) -> Karnataka | AB62: =TRIM(J62) -> Bengaluru | AC62: =TRIM(K62) -> Electronics | AD62: =TRIM(M62) -> Galaxy S24 | AE62: =TRIM(N62) -> Samsung | AF62: =TRIM(X62) -> Bengaluru Hub | AG62: =TRIM(Y62) -> James Wells
A63: ORD100061 | B63: CUST10061 | C63: Vincent Anderson | D63: Female | E63: 31 | F63: Amazon | G63: 46026 | H63: 45677 | I63: Telangana | J63: Hyderabad | K63: Electronics | L63: P3580 | M63: iPhone 15 | N63: Apple | O63: 1 | P63: 8685 | Q63: 9884.19 | R63: 0 | S63: 9884.19 | T63: 1199.19 | U63: Debit Card | V63: Cancelled | W63: 2 | X63: Hyderabad Hub | Y63: Mary Nichols | Z63: =TRIM(C63) -> Vincent Anderson | AA63: =TRIM(I63) -> Telangana | AB63: =TRIM(J63) -> Hyderabad | AC63: =TRIM(K63) -> Electronics | AD63: =TRIM(M63) -> iPhone 15 | AE63: =TRIM(N63) -> Apple | AF63: =TRIM(X63) -> Hyderabad Hub | AG63: =TRIM(Y63) -> Mary Nichols
A64: ORD100062 | B64: CUST10062 | C64: Jennifer Simpson | D64: Female | E64: 36 | F64: Flipkart | G64: 45492 | H64: 45496 | I64: Karnataka | J64: Bengaluru | K64: Fashion | L64: P1951 | M64: Air Max Shoes | N64: Nike | O64: 2 | P64: 19331 | Q64: 25103.5 | R64: 10 | S64: 45186.3 | T64: 11545 | U64: UPI | V64: Cancelled | W64: 5 | X64: Bengaluru Hub | Y64: Melanie Garrett | Z64: =TRIM(C64) -> Jennifer Simpson | AA64: =TRIM(I64) -> Karnataka | AB64: =TRIM(J64) -> Bengaluru | AC64: =TRIM(K64) -> Fashion | AD64: =TRIM(M64) -> Air Max Shoes | AE64: =TRIM(N64) -> Nike | AF64: =TRIM(X64) -> Bengaluru Hub | AG64: =TRIM(Y64) -> Melanie Garrett
...

Sheet Data_Quality_Report
A1: Issue | B1: Before | C1: After
A2: Duplicate Records | B2: 210 | C2: 0
A3: Missing Values | B3: =COUNTBLANK(Sales_Analysis.xlsx!A1:Y5251) -> 359 | C3: 0
A4: Invalid State Names | B4: 100 | C4: 0
A5: Invalid Categories | B5: 100 | C5: 0
A6: Blank Product Names | B6: 120 | C6: 0

Sheet Data_Profiling
A1: Metric | B1: Value
A2: Total Records | B2: =ROWS(Sales_Analysis.xlsx!S2:Y5251) -> 5250
A3: Total Columns | B3: =COLUMNS(Sales_Analysis.xlsx!A1:Y1) -> 25
A4: Duplicate Records | B4: 210
A5: Missing Values | B5: =COUNTBLANK(Sales_Analysis.xlsx!A1:Y5251) -> 359
A6: Unique States | B6: =COUNT(_xlfn.UNIQUE(Cleaned_Data!AA2:AA5040)) -> 0
A7: Unique Categories | B7: =COUNT(_xlfn.UNIQUE(Cleaned_Data!AC2:AC5040)) -> 0
A8: Date Range | B8: =MAX(Cleaned_Data!G2:H5040)-MIN(Cleaned_Data!G2:H5040) -> 730
A11: =MIN(Cleaned_Data!G2:H5040) -> 45468 | B11: minimum date
A12: =MAX(Cleaned_Data!G2:H5040) -> 46198 | B12: maximum date

Sheet KPI_Summary
A1: A | B1: B
A2: KPI | B2: Value
A3: Total Sales | B3: =SUM(Cleaned_Data!S2:S5040) -> 2.6642113e+08
A4: Total Profit | B4: =SUM(Cleaned_Data!T2:T5040) -> 68063308
A5: Total Orders | B5: =COUNTA(Cleaned_Data!A2:A5040) -> 5039
A6: Total Quantity | B6: =SUM(Cleaned_Data!O2:O5040) -> 15223
A7: Average Rating | B7: =AVERAGE(Cleaned_Data!W2:W5040) -> 3.0075412
A8: Average Order Value | B8: =B3/B5 -> 52871.826

Sheet Pivot_Tables
A1: Row Labels | B1: Sum of Sales | F1: Row Labels | G1: Sum of Sales
A2: Amazon | B2: 1.3521612e+08 | F2: Delhi | G2: 50618172
A3: Flipkart | B3: 1.3120501e+08 | F3: Karnataka | G3: 51228078
A4: Grand Total | B4: 2.6642113e+08 | F4: Maharashtra | G4: 59647790
F5: Tamil Nadu | G5: 54112931
F6: Telangana | G6: 50814161
F7: Grand Total | G7: 2.6642113e+08
A20: Row Labels | B20: Sum of Sales | F20: Row Labels | G20: Sum of Sales
A21: Beauty | B21: 43006179 | F21: Jan | G21: 25599083
A22: Electronics | B22: 92570302 | F22: Feb | G22: 18973339
A23: Fashion | B23: 43061382 | F23: Mar | G23: 21618413
A24: Grocery | B24: 43849090 | F24: Apr | G24: 22460524
A25: Home | B25: 43934178 | F25: May | G25: 22281358
A26: Grand Total | B26: 2.6642113e+08 | F26: Jun | G26: 21969322
F27: Jul | G27: 22247075
F28: Aug | G28: 22082090
F29: Sep | G29: 20131984
F30: Oct | G30: 20580217
F31: Nov | G31: 22408764
F32: Dec | G32: 26068962
F33: Grand Total | G33: 2.6642113e+08
A40: Row Labels | B40: Sum of Sales | F40: Row Labels | G40: Sum of Sales
A41: Apple | B41: 43010153 | F41: COD | G41: 67396019
A42: Fortune | B42: 44613246 | F42: Credit Card | G42: 72141526
A43: Loreal | B43: 44269538 | F43: Debit Card | G43: 63881253
A44: Nike | B44: 43745164 | F44: UPI | G44: 63002333
A45: Prestige | B45: 44910669 | F45: Grand Total | G45: 2.6642113e+08
A46: Samsung | B46: 45872362
A47: Grand Total | B47: 2.6642113e+08
A60: Row Labels | B60: Count of Order_ID
A61: Cancelled | B61: 1293
A62: Delivered | B62: 1217
A63: In Transit | B63: 1262
A64: Returned | B64: 1267
A65: Grand Total | B65: 5039

Sheet Dashboard_Excel
